This is a testharness.js-based test.
FAIL Do not crash when exceptions are thrown during keyframe iteration. Test bug: need to pass exception to assert_throws()
Harness: the test ran to completion.

